<?xml version="1.0"?>
<robot xmlns:xacro="http://www.ros.org/wiki/xacro" name="robot">

    <material name="white">
        <color rgba="1 1 1 1" />
    </material>

    <material name="orange">
        <color rgba="1 0.3 0.1 1" />
    </material>

    <material name="blue">
        <color rgba="0.2 0.2 1 1" />
    </material>

    <material name="black">
        <color rgba="0 0 0 1" />
    </material>

    <!-- BASE LINK -->

    <link name="base_link">
        <!-- <collision>
            <geometry>
                <box size="0.01 0.01 0.00000001"/>
            </geometry>
        </collision> -->
    </link>


    <!-- BASE_FOOTPRINT LINK -->

    <joint name="base_footprint_joint" type="fixed">
        <parent link="base_link"/>
        <child link="base_footprint"/>
        <origin xyz="0 0 0" rpy="0 0 0"/>
    </joint>

    <link name="base_footprint">
    </link>

    <!-- CHASSIS LINK -->

    <joint name="chassis_joint" type="fixed">
        <parent link="base_link"/>
        <child link="chassis"/>
        <origin xyz="-0.3 0 0.3"/>
    </joint>

    <link name="chassis">
        <inertial>
            <origin xyz="0.6 0 0.15"/>
            <mass value="80.0"/>
            <inertia ixx="5.0" iyy="5.0" izz="2.5" ixy="0.0" ixz="0.0" iyz="0.0"/>
        </inertial>
        <visual>
            <origin xyz="0.6 0 0.15"/>
            <geometry>
                <box size="1.2 0.65 0.3"/>
            </geometry>
            <material name="orange"/>
        </visual>
        <collision>
            <origin xyz="0.6 0 0.15"/>
            <geometry>
                <box size="1.2 0.65 0.3"/>
            </geometry>
        </collision>
    </link>

    <!-- LEFT WHEEL LINK -->

    <joint name="left_wheel_joint" type="continuous">
        <parent link="base_link"/>
        <child link="left_wheel"/>
        <origin xyz="0 0.3 0.3" rpy="-${pi/2} 0 0"/>
        <axis xyz="0 0 1"/>
        <dynamics damping="0.1" friction="0.1"/>  <!-- Add friction and damping -->
    </joint>

    <link name="left_wheel">
        <inertial>
            <origin xyz="0 0 0"/>
            <mass value="2.0"/>
            <inertia ixx="0.02" iyy="0.02" izz="0.01" ixy="0.0" ixz="0.0" iyz="0.0"/>
        </inertial>
        <visual>
            <geometry>
                <cylinder radius="0.19" length="0.06"/>
            </geometry>
            <material name="black"/>
        </visual>
        <collision>
            <geometry>
                <cylinder radius="0.19" length="0.06"/>
            </geometry>
        </collision>
    </link>

    <!-- RIGHT WHEEL LINK -->

    <joint name="right_wheel_joint" type="continuous">
        <parent link="base_link"/>
        <child link="right_wheel"/>
        <origin xyz="0 -0.3 0.3" rpy="${pi/2} 0 0"/>
        <axis xyz="0 0 -1"/>
        <dynamics damping="0.1" friction="0.1"/>  <!-- Add friction and damping -->
    </joint>

    <link name="right_wheel">
        <inertial>
            <origin xyz="0 0 0"/>
            <mass value="2.0"/>
            <inertia ixx="0.02" iyy="0.02" izz="0.01" ixy="0.0" ixz="0.0" iyz="0.0"/>
        </inertial>
        <visual>
            <geometry>
                <cylinder radius="0.19" length="0.06"/>
            </geometry>
            <material name="black"/>
        </visual>
        <collision>
            <geometry>
                <cylinder radius="0.19" length="0.06"/>
            </geometry>
        </collision>
    </link>

    <!-- LEFT CASTER WHEEL -->

    <joint name="left_caster_joint" type="continuous">
        <parent link="base_link"/>
        <child link="left_caster_mount"/>
        <origin xyz="0.6 0.2 0.25" rpy="0 0 0"/>
        <axis xyz="0 0 1"/>
        <dynamics damping="0.1" friction="0.1"/>  <!-- Add friction and damping -->
    </joint>

    <link name="left_caster_mount">
        <inertial>
            <origin xyz="0 0 0"/>
            <mass value="1.0"/>
            <inertia ixx="0.005" iyy="0.005" izz="0.003" ixy="0.0" ixz="0.0" iyz="0.0"/>
        </inertial>
        <visual>
            <geometry>
                <cylinder radius="0.02" length="0.1"/>
            </geometry>
            <material name="blue"/>
        </visual>
        <collision>
            <geometry>
                <cylinder radius="0.02" length="0.1"/>
            </geometry>
        </collision>
    </link>

    <joint name="left_caster_wheel_joint" type="continuous">
        <parent link="left_caster_mount"/>
        <child link="left_caster_wheel"/>
        <origin xyz="0.05 0 -0.06" rpy="${pi/2} 0 0"/>
        <axis xyz="0 0 1"/>
        <dynamics damping="0.1" friction="0.1"/>  <!-- Add friction and damping -->
    </joint>

    <link name="left_caster_wheel">
        <inertial>
            <origin xyz="0 0 0"/>
            <mass value="0.5"/>
            <inertia ixx="0.001" iyy="0.001" izz="0.0005" ixy="0.0" ixz="0.0" iyz="0.0"/>
        </inertial>
        <visual>
            <geometry>
                <cylinder radius="0.1" length="0.02"/>
            </geometry>
            <material name="black"/>
        </visual>
        <collision>
            <geometry>
                <cylinder radius="0.1" length="0.02"/>
            </geometry>
        </collision>
    </link>

    <!-- RIGHT CASTER WHEEL -->

    <joint name="right_caster_joint" type="continuous">
        <parent link="base_link"/>
        <child link="right_caster_mount"/>
        <origin xyz="0.6 -0.2 0.25" rpy="0 0 0"/>
        <axis xyz="0 0 1"/>
        <dynamics damping="0.1" friction="0.1"/>  <!-- Add friction and damping -->
    </joint>

    <link name="right_caster_mount">
        <inertial>
            <origin xyz="0 0 0"/>
            <mass value="1.0"/>
            <inertia ixx="0.005" iyy="0.005" izz="0.003" ixy="0.0" ixz="0.0" iyz="0.0"/>
        </inertial>
        <visual>
            <geometry>
                <cylinder radius="0.02" length="0.1"/>
            </geometry>
            <material name="blue"/>
        </visual>
        <collision>
            <geometry>
                <cylinder radius="0.02" length="0.1"/>
            </geometry>
        </collision>
    </link>

    <joint name="right_caster_wheel_joint" type="continuous">
        <parent link="right_caster_mount"/>
        <child link="right_caster_wheel"/>
        <origin xyz="0.05 0 -0.06" rpy="${pi/2} 0 0"/>
        <axis xyz="0 0 1"/>
        <dynamics damping="0.1" friction="0.1"/>  <!-- Add friction and damping -->
    </joint>

    <link name="right_caster_wheel">
        <inertial>
            <origin xyz="0 0 0"/>
            <mass value="0.5"/>
            <inertia ixx="0.001" iyy="0.001" izz="0.0005" ixy="0.0" ixz="0.0" iyz="0.0"/>
        </inertial>
        <visual>
            <geometry>
                <cylinder radius="0.1" length="0.02"/>
            </geometry>
            <material name="black"/>
        </visual>
        <collision>
            <geometry>
                <cylinder radius="0.1" length="0.02"/>
            </geometry>
        </collision>
    </link>

</robot>
